<?xml version="1.0" ?>
<!-- Generated using onshape-to-robot -->
<!-- Onshape https://cad.onshape.com/documents/31ca51e87164d5a2ae3b11dc/w/1e07aa3f18f08d453ac8b6a1/e/be108145cc25fea61866c58d -->
<robot name="perseverance">
  <!-- base_link_centered: kinematic centre of the rover, REP-105 oriented -->
  <!-- x=forward, y=left, z=up. z is NOT ground-projected (that is base_footprint). -->
  <!-- base_footprint is published dynamically by the state estimation node. -->
  <link name="base_link_centered"/>

  <joint name="base_link_centered_to_base_link" type="fixed">
    <parent link="base_link_centered"/>
    <child link="base_link"/>
    <!-- xyz: base_link origin in base_link_centered frame (auto-computed) -->
    <!-- rpy: CAD-frame to REP-105 correction (yaw=90.0 deg) -->
    <origin xyz="-0.015030 0.025000 0.000000" rpy="0.000000 0.000000 1.570796"/>
  </joint>

  <!-- Link base_link -->
  <link name="base_link">
    <inertial>
      <origin xyz="-0.0234123 -0.0139367 0.0131799" rpy="0 0 0"/>
      <mass value="1.18472"/>
      <inertia ixx="0.00923101" ixy="-0.00018279" ixz="4.31897e-06" iyy="0.00946676" iyz="0.000137098" izz="0.0179872"/>
    </inertial>
    <!-- Part rightbogie -->
    <visual>
      <origin xyz="-0.15 0.0418583 -0.00306575" rpy="0 -0 -1.5708"/>
      <geometry>
        <mesh filename="package://perseverance/urdf/rightbogie.stl"/>
      </geometry>
      <material name="rightbogie_material">
        <color rgba="0.262745 0.282353 0.301961 1"/>
      </material>
    </visual>
    <collision>
      <origin xyz="-0.15 0.0418583 -0.00306575" rpy="0 -0 -1.5708"/>
      <geometry>
        <mesh filename="package://perseverance/urdf/rightbogie.stl"/>
      </geometry>
    </collision>
    <!-- Part bevel_0_85m_18t_45deg -->
    <visual>
      <origin xyz="-0.037226 -0.042 0.024" rpy="-0 1.5708 0"/>
      <geometry>
        <mesh filename="package://perseverance/urdf/bevel_0_85m_18t_45deg.stl"/>
      </geometry>
      <material name="bevel_0_85m_18t_45deg_material">
        <color rgba="0.729412 0.25098 0.105882 1"/>
      </material>
    </visual>
    <collision>
      <origin xyz="-0.037226 -0.042 0.024" rpy="-0 1.5708 0"/>
      <geometry>
        <mesh filename="package://perseverance/urdf/bevel_0_85m_18t_45deg.stl"/>
      </geometry>
    </collision>
    <!-- Part base_link -->
    <visual>
      <origin xyz="-0.025 1.35308e-15 1.78677e-16" rpy="0 -0 0"/>
      <geometry>
        <mesh filename="package://perseverance/urdf/base_link.stl"/>
      </geometry>
      <material name="base_link_material">
        <color rgba="0.811765 0.858824 0.898039 1"/>
      </material>
    </visual>
    <collision>
      <origin xyz="-0.025 1.35308e-15 1.78677e-16" rpy="0 -0 0"/>
      <geometry>
        <mesh filename="package://perseverance/urdf/base_link.stl"/>
      </geometry>
    </collision>
    <!-- Part bevel_0_85m_18t_45deg_2 -->
    <visual>
      <origin xyz="-0.012774 -0.042 0.024" rpy="-1.3494e-79 -1.5708 0"/>
      <geometry>
        <mesh filename="package://perseverance/urdf/bevel_0_85m_18t_45deg.stl"/>
      </geometry>
      <material name="bevel_0_85m_18t_45deg_2_material">
        <color rgba="0.729412 0.25098 0.105882 1"/>
      </material>
    </visual>
    <collision>
      <origin xyz="-0.012774 -0.042 0.024" rpy="-1.3494e-79 -1.5708 0"/>
      <geometry>
        <mesh filename="package://perseverance/urdf/bevel_0_85m_18t_45deg.stl"/>
      </geometry>
    </collision>
    <!-- Part mg995 -->
    <visual>
      <origin xyz="-0.1425 -0.140031 0.043" rpy="3.14159 -0 -3.14159"/>
      <geometry>
        <mesh filename="package://perseverance/urdf/mg995.stl"/>
      </geometry>
      <material name="mg995_material">
        <color rgba="0.792157 0.819608 0.933333 1"/>
      </material>
    </visual>
    <collision>
      <origin xyz="-0.1425 -0.140031 0.043" rpy="3.14159 -0 -3.14159"/>
      <geometry>
        <mesh filename="package://perseverance/urdf/mg995.stl"/>
      </geometry>
    </collision>
    <!-- Part mg995_2 -->
    <visual>
      <origin xyz="-0.150764 0.100122 0.0432278" rpy="3.14159 -0 1.74533"/>
      <geometry>
        <mesh filename="package://perseverance/urdf/mg995.stl"/>
      </geometry>
      <material name="mg995_2_material">
        <color rgba="0.792157 0.819608 0.933333 1"/>
      </material>
    </visual>
    <collision>
      <origin xyz="-0.150764 0.100122 0.0432278" rpy="3.14159 -0 1.74533"/>
      <geometry>
        <mesh filename="package://perseverance/urdf/mg995.stl"/>
      </geometry>
    </collision>
    <!-- Part mg995_3 -->
    <visual>
      <origin xyz="0.0925 -0.140031 0.043" rpy="3.14159 -0 -2.01228e-16"/>
      <geometry>
        <mesh filename="package://perseverance/urdf/mg995.stl"/>
      </geometry>
      <material name="mg995_3_material">
        <color rgba="0.792157 0.819608 0.933333 1"/>
      </material>
    </visual>
    <collision>
      <origin xyz="0.0925 -0.140031 0.043" rpy="3.14159 -0 -2.01228e-16"/>
      <geometry>
        <mesh filename="package://perseverance/urdf/mg995.stl"/>
      </geometry>
    </collision>
    <!-- Part leftrocker -->
    <visual>
      <origin xyz="0.065 -0.042 0.024" rpy="0 -0 -1.5708"/>
      <geometry>
        <mesh filename="package://perseverance/urdf/leftrocker.stl"/>
      </geometry>
      <material name="leftrocker_material">
        <color rgba="0.262745 0.282353 0.301961 1"/>
      </material>
    </visual>
    <collision>
      <origin xyz="0.065 -0.042 0.024" rpy="0 -0 -1.5708"/>
      <geometry>
        <mesh filename="package://perseverance/urdf/leftrocker.stl"/>
      </geometry>
    </collision>
    <!-- Part rightrocker -->
    <visual>
      <origin xyz="-0.115 -0.042 0.024" rpy="0 -0 -1.5708"/>
      <geometry>
        <mesh filename="package://perseverance/urdf/rightrocker.stl"/>
      </geometry>
      <material name="rightrocker_material">
        <color rgba="0.262745 0.282353 0.301961 1"/>
      </material>
    </visual>
    <collision>
      <origin xyz="-0.115 -0.042 0.024" rpy="0 -0 -1.5708"/>
      <geometry>
        <mesh filename="package://perseverance/urdf/rightrocker.stl"/>
      </geometry>
    </collision>
    <!-- Part mg995_4 -->
    <visual>
      <origin xyz="0.100764 0.100122 0.0432278" rpy="3.14159 -0 1.39626"/>
      <geometry>
        <mesh filename="package://perseverance/urdf/mg995.stl"/>
      </geometry>
      <material name="mg995_4_material">
        <color rgba="0.792157 0.819608 0.933333 1"/>
      </material>
    </visual>
    <collision>
      <origin xyz="0.100764 0.100122 0.0432278" rpy="3.14159 -0 1.39626"/>
      <geometry>
        <mesh filename="package://perseverance/urdf/mg995.stl"/>
      </geometry>
    </collision>
    <!-- Part leftbogie -->
    <visual>
      <origin xyz="0.1 0.0418583 -0.00306575" rpy="0 -0 -1.5708"/>
      <geometry>
        <mesh filename="package://perseverance/urdf/leftbogie.stl"/>
      </geometry>
      <material name="leftbogie_material">
        <color rgba="0.262745 0.282353 0.301961 1"/>
      </material>
    </visual>
    <collision>
      <origin xyz="0.1 0.0418583 -0.00306575" rpy="0 -0 -1.5708"/>
      <geometry>
        <mesh filename="package://perseverance/urdf/leftbogie.stl"/>
      </geometry>
    </collision>
  </link>
  <!-- Link rearsteeringarm -->
  <link name="rearsteeringarm">
    <inertial>
      <origin xyz="0.0165409 4.47932e-09 -0.0224062" rpy="0 0 0"/>
      <mass value="0.0308339"/>
      <inertia ixx="1.44735e-05" ixy="-3.36456e-13" ixz="9.69136e-07" iyy="1.74258e-05" iyz="-2.84758e-13" izz="5.38307e-06"/>
    </inertial>
    <!-- Part rearsteeringarm -->
    <visual>
      <origin xyz="0 0 -0.005" rpy="9.24446e-33 -2.82529e-32 -4.77087e-18"/>
      <geometry>
        <mesh filename="package://perseverance/urdf/rearsteeringarm.stl"/>
      </geometry>
      <material name="rearsteeringarm_material">
        <color rgba="0.458824 0.105882 0 1"/>
      </material>
    </visual>
    <collision>
      <origin xyz="0 0 -0.005" rpy="9.24446e-33 -2.82529e-32 -4.77087e-18"/>
      <geometry>
        <mesh filename="package://perseverance/urdf/rearsteeringarm.stl"/>
      </geometry>
    </collision>
  </link>
  <!-- Link wheel -->
  <link name="wheel">
    <inertial>
      <origin xyz="-3.19706e-19 3.11993e-18 0.00460287" rpy="0 0 0"/>
      <mass value="0.0820664"/>
      <inertia ixx="3.08808e-05" ixy="-3.64091e-55" ixz="-1.42616e-21" iyy="3.08808e-05" iyz="1.12352e-54" izz="5.62507e-05"/>
    </inertial>
    <!-- Part wheel -->
    <visual>
      <origin xyz="0 0 -0.005" rpy="-1.5708 1.35456e-17 3.31859e-65"/>
      <geometry>
        <mesh filename="package://perseverance/urdf/wheel.stl"/>
      </geometry>
      <material name="wheel_material">
        <color rgba="0.498039 0.498039 0.498039 1"/>
      </material>
    </visual>
    <collision>
      <origin xyz="0 0 -0.005" rpy="-1.5708 1.35456e-17 3.31859e-65"/>
      <geometry>
        <mesh filename="package://perseverance/urdf/wheel.stl"/>
      </geometry>
    </collision>
  </link>
  <!-- Joint from rearsteeringarm to wheel -->
  <joint name="bl_wheel" type="continuous">
    <origin xyz="-0.005 2.77556e-17 -0.0463814" rpy="-1.5708 1.249e-16 -1.5708"/>
    <parent link="rearsteeringarm"/>
    <child link="wheel"/>
    <axis xyz="0 0 1"/>
    <limit effort="10" velocity="10"/>
  </joint>
  <!-- Joint from base_link to rearsteeringarm -->
  <joint name="bl_steering" type="revolute">
    <origin xyz="0.1025 0.10997 -0.00127218" rpy="-1.249e-16 4.18641e-16 3.141593"/>
    <parent link="base_link"/>
    <child link="rearsteeringarm"/>
    <axis xyz="0 0 1"/>
    <limit effort="10" velocity="10" lower="-0.610865" upper="0.610865"/>
  </joint>
  <!-- Link rearsteeringarm_2 -->
  <link name="rearsteeringarm_2">
    <inertial>
      <origin xyz="0.0165409 4.47932e-09 -0.0224062" rpy="0 0 0"/>
      <mass value="0.0308339"/>
      <inertia ixx="1.44735e-05" ixy="-3.36456e-13" ixz="9.69136e-07" iyy="1.74258e-05" iyz="-2.84758e-13" izz="5.38307e-06"/>
    </inertial>
    <!-- Part rearsteeringarm_2 -->
    <visual>
      <origin xyz="2.77556e-17 2.77556e-17 -0.005" rpy="-8.84344e-75 -0 -7.75341e-18"/>
      <geometry>
        <mesh filename="package://perseverance/urdf/rearsteeringarm.stl"/>
      </geometry>
      <material name="rearsteeringarm_2_material">
        <color rgba="0.458824 0.105882 0 1"/>
      </material>
    </visual>
    <collision>
      <origin xyz="2.77556e-17 2.77556e-17 -0.005" rpy="-8.84344e-75 -0 -7.75341e-18"/>
      <geometry>
        <mesh filename="package://perseverance/urdf/rearsteeringarm.stl"/>
      </geometry>
    </collision>
  </link>
  <!-- Link wheel_2 -->
  <link name="wheel_2">
    <inertial>
      <origin xyz="2.74893e-17 3.11993e-18 0.00460287" rpy="0 0 0"/>
      <mass value="0.0820664"/>
      <inertia ixx="3.08808e-05" ixy="3.5356e-93" ixz="-7.5456e-22" iyy="3.08808e-05" iyz="5.5184e-80" izz="5.62507e-05"/>
    </inertial>
    <!-- Part wheel_2 -->
    <visual>
      <origin xyz="2.77556e-17 0 -0.005" rpy="-1.5708 1.93111e-18 9.91647e-75"/>
      <geometry>
        <mesh filename="package://perseverance/urdf/wheel.stl"/>
      </geometry>
      <material name="wheel_2_material">
        <color rgba="0.498039 0.498039 0.498039 1"/>
      </material>
    </visual>
    <collision>
      <origin xyz="2.77556e-17 0 -0.005" rpy="-1.5708 1.93111e-18 9.91647e-75"/>
      <geometry>
        <mesh filename="package://perseverance/urdf/wheel.stl"/>
      </geometry>
    </collision>
  </link>
  <!-- Joint from rearsteeringarm_2 to wheel_2 -->
  <joint name="br_wheel" type="continuous">
    <origin xyz="-0.005 5.55112e-17 -0.0463814" rpy="1.5708 -0 1.5708"/>
    <parent link="rearsteeringarm_2"/>
    <child link="wheel_2"/>
    <axis xyz="0 0 1"/>
    <limit effort="10" velocity="10"/>
  </joint>
  <!-- Joint from base_link to rearsteeringarm_2 -->
  <joint name="br_steering" type="revolute">
    <origin xyz="-0.1525 0.10997 -0.00127218" rpy="4.22436e-59 -1.37735e-59 0.000000"/>
    <parent link="base_link"/>
    <child link="rearsteeringarm_2"/>
    <axis xyz="0 0 1"/>
    <limit effort="10" velocity="10" lower="-0.610865" upper="0.610865"/>
  </joint>
  <!-- Link frontsteeringarm -->
  <link name="frontsteeringarm">
    <inertial>
      <origin xyz="0.0163817 3.64678e-09 -0.0208537" rpy="0 0 0"/>
      <mass value="0.0304253"/>
      <inertia ixx="1.27176e-05" ixy="-3.50002e-13" ixz="8.997e-07" iyy="1.5628e-05" iyz="-1.30031e-13" izz="5.30164e-06"/>
    </inertial>
    <!-- Part frontsteeringarm -->
    <visual>
      <origin xyz="0 2.77556e-17 -0.005" rpy="0 -0 9.24446e-33"/>
      <geometry>
        <mesh filename="package://perseverance/urdf/frontsteeringarm.stl"/>
      </geometry>
      <material name="frontsteeringarm_material">
        <color rgba="0.458824 0.105882 0 1"/>
      </material>
    </visual>
    <collision>
      <origin xyz="0 2.77556e-17 -0.005" rpy="0 -0 9.24446e-33"/>
      <geometry>
        <mesh filename="package://perseverance/urdf/frontsteeringarm.stl"/>
      </geometry>
    </collision>
  </link>
  <!-- Link wheel_3 -->
  <link name="wheel_3">
    <inertial>
      <origin xyz="-1.47648e-19 3.11993e-18 0.00460287" rpy="0 0 0"/>
      <mass value="0.0820664"/>
      <inertia ixx="3.08808e-05" ixy="0" ixz="-5.47239e-37" iyy="3.08808e-05" iyz="0" izz="5.62507e-05"/>
    </inertial>
    <!-- Part wheel_3 -->
    <visual>
      <origin xyz="0 0 -0.005" rpy="-1.5708 -2.15704e-32 0"/>
      <geometry>
        <mesh filename="package://perseverance/urdf/wheel.stl"/>
      </geometry>
      <material name="wheel_3_material">
        <color rgba="0.498039 0.498039 0.498039 1"/>
      </material>
    </visual>
    <collision>
      <origin xyz="0 0 -0.005" rpy="-1.5708 -2.15704e-32 0"/>
      <geometry>
        <mesh filename="package://perseverance/urdf/wheel.stl"/>
      </geometry>
    </collision>
  </link>
  <!-- Joint from frontsteeringarm to wheel_3 -->
  <joint name="fl_wheel" type="continuous">
    <origin xyz="-0.005 2.77556e-17 -0.0433189" rpy="-1.5708 -0 -1.5708"/>
    <parent link="frontsteeringarm"/>
    <child link="wheel_3"/>
    <axis xyz="0 0 1"/>
    <limit effort="10" velocity="10"/>
  </joint>
  <!-- Joint from base_link to frontsteeringarm -->
  <joint name="fl_steering" type="revolute">
    <origin xyz="0.1025 -0.140031 -0.0015" rpy="0 -0 3.14159"/>
    <parent link="base_link"/>
    <child link="frontsteeringarm"/>
    <axis xyz="0 0 1"/>
    <limit effort="10" velocity="10" lower="-0.610865" upper="0.610865"/>
  </joint>
  <!-- Link frontsteeringarm_2 -->
  <link name="frontsteeringarm_2">
    <inertial>
      <origin xyz="-0.0163817 -3.64678e-09 -0.0208537" rpy="0 0 0"/>
      <mass value="0.0304253"/>
      <inertia ixx="1.27176e-05" ixy="-3.50002e-13" ixz="-8.997e-07" iyy="1.5628e-05" iyz="1.30031e-13" izz="5.30164e-06"/>
    </inertial>
    <!-- Part frontsteeringarm_2 -->
    <visual>
      <origin xyz="0 2.77556e-17 -0.005" rpy="0 -0 3.14159"/>
      <geometry>
        <mesh filename="package://perseverance/urdf/frontsteeringarm.stl"/>
      </geometry>
      <material name="frontsteeringarm_2_material">
        <color rgba="0.458824 0.105882 0 1"/>
      </material>
    </visual>
    <collision>
      <origin xyz="0 2.77556e-17 -0.005" rpy="0 -0 3.14159"/>
      <geometry>
        <mesh filename="package://perseverance/urdf/frontsteeringarm.stl"/>
      </geometry>
    </collision>
  </link>
  <!-- Link wheel_4 -->
  <link name="wheel_4">
    <inertial>
      <origin xyz="-1.47648e-19 3.11993e-18 0.00460287" rpy="0 0 0"/>
      <mass value="0.0820664"/>
      <inertia ixx="3.08808e-05" ixy="1.05339e-100" ixz="-2.68495e-37" iyy="3.08808e-05" iyz="-3.41845e-68" izz="5.62507e-05"/>
    </inertial>
    <!-- Part wheel_4 -->
    <visual>
      <origin xyz="0 0 -0.005" rpy="-1.5708 3.08149e-33 0"/>
      <geometry>
        <mesh filename="package://perseverance/urdf/wheel.stl"/>
      </geometry>
      <material name="wheel_4_material">
        <color rgba="0.498039 0.498039 0.498039 1"/>
      </material>
    </visual>
    <collision>
      <origin xyz="0 0 -0.005" rpy="-1.5708 3.08149e-33 0"/>
      <geometry>
        <mesh filename="package://perseverance/urdf/wheel.stl"/>
      </geometry>
    </collision>
  </link>
  <!-- Joint from frontsteeringarm_2 to wheel_4 -->
  <joint name="fr_wheel" type="continuous">
    <origin xyz="0.005 2.77556e-17 -0.0433189" rpy="1.5708 3.93984e-31 -1.5708"/>
    <parent link="frontsteeringarm_2"/>
    <child link="wheel_4"/>
    <axis xyz="0 0 1"/>
    <limit effort="10" velocity="10"/>
  </joint>
  <!-- Joint from base_link to frontsteeringarm_2 -->
  <joint name="fr_steering" type="revolute">
    <origin xyz="-0.1525 -0.140031 -0.0015" rpy="0 -0 -3.14159"/>
    <parent link="base_link"/>
    <child link="frontsteeringarm_2"/>
    <axis xyz="0 0 1"/>
    <limit effort="10" velocity="10" lower="-0.610865" upper="0.610865"/>
  </joint>
  <!-- Link wheel_5 -->
  <link name="wheel_5">
    <inertial>
      <origin xyz="-1.47648e-19 3.11993e-18 0.00460287" rpy="0 0 0"/>
      <mass value="0.0820664"/>
      <inertia ixx="3.08808e-05" ixy="0" ixz="6.18563e-36" iyy="3.08808e-05" iyz="0" izz="5.62507e-05"/>
    </inertial>
    <!-- Part wheel_5 -->
    <visual>
      <origin xyz="0 0 -0.005" rpy="-1.5708 -4.31408e-32 0"/>
      <geometry>
        <mesh filename="package://perseverance/urdf/wheel.stl"/>
      </geometry>
      <material name="wheel_5_material">
        <color rgba="0.498039 0.498039 0.498039 1"/>
      </material>
    </visual>
    <collision>
      <origin xyz="0 0 -0.005" rpy="-1.5708 -4.31408e-32 0"/>
      <geometry>
        <mesh filename="package://perseverance/urdf/wheel.stl"/>
      </geometry>
    </collision>
  </link>
  <!-- Joint from base_link to wheel_5 -->
  <joint name="mr_wheel" type="continuous">
    <origin xyz="-0.177 -0.00814152 -0.0476535" rpy="1.5708 -0 1.5708"/>
    <parent link="base_link"/>
    <child link="wheel_5"/>
    <axis xyz="0 0 1"/>
    <limit effort="10" velocity="10"/>
  </joint>
  <!-- Link wheel_6 -->
  <link name="wheel_6">
    <inertial>
      <origin xyz="1.05344e-19 3.11993e-18 -0.000397125" rpy="0 0 0"/>
      <mass value="0.0820664"/>
      <inertia ixx="3.08808e-05" ixy="0" ixz="9.67354e-20" iyy="3.08808e-05" iyz="0" izz="5.62507e-05"/>
    </inertial>
    <!-- Part wheel_6 -->
    <visual>
      <origin xyz="-1.04083e-17 0 -0.01" rpy="-1.5708 -1.11022e-15 0"/>
      <geometry>
        <mesh filename="package://perseverance/urdf/wheel.stl"/>
      </geometry>
      <material name="wheel_6_material">
        <color rgba="0.498039 0.498039 0.498039 1"/>
      </material>
    </visual>
    <collision>
      <origin xyz="-1.04083e-17 0 -0.01" rpy="-1.5708 -1.11022e-15 0"/>
      <geometry>
        <mesh filename="package://perseverance/urdf/wheel.stl"/>
      </geometry>
    </collision>
  </link>
  <!-- Joint from base_link to wheel_6 -->
  <joint name="ml_wheel" type="continuous">
    <origin xyz="0.122 -0.00814152 -0.0476535" rpy="1.5708 -0 -1.5708"/>
    <parent link="base_link"/>
    <child link="wheel_6"/>
    <axis xyz="0 0 1"/>
    <limit effort="10" velocity="10"/>
  </joint>
</robot>
